Bug in problem.py but it ended up being really close to the original attempt at longest_subsequence.
